[34m[1mwandb[39m[22m: 500 encountered ({"error":"internal database error"}), retrying request
[34m[1mwandb[39m[22m: Network error resolved after 0:00:17.692375, resuming normal operation.
Traceback (most recent call last):
  File "run.py", line 133, in <module>
    train_loop()
  File "run.py", line 108, in train_loop
    sim_one_checkpoint.log_metrics(wandb)
AttributeError: 'simulation_one' object has no attribute 'log_metrics'
Traceback (most recent call last):
  File "run.py", line 133, in <module>
    train_loop()
  File "run.py", line 108, in train_loop
    sim_one_checkpoint.log_metrics(wandb)
AttributeError: 'simulation_one' object has no attribute 'log_metrics'